Internal Server Error: /nuevo_evento/detalle-evento/1/
Traceback (most recent call last):
  File "C:\Users\ga214\Desktop\taller\proyectofinal\.venv\Lib\site-packages\django\db\backends\utils.py", line 105, in _execute
    return self.cursor.execute(sql, params)
           ^^^^^^^^^^^^^^^^^^^^^^^^^^^^^^^^
  File "C:\Users\ga214\Desktop\taller\proyectofinal\.venv\Lib\site-packages\django\db\backends\sqlite3\base.py", line 354, in execute
    return super().execute(query, params)
           ^^^^^^^^^^^^^^^^^^^^^^^^^^^^^^
sqlite3.IntegrityError: NOT NULL constraint failed: nuevo_evento_nota.usuario_id

The above exception was the direct cause of the following exception:

Traceback (most recent call last):
  File "C:\Users\ga214\Desktop\taller\proyectofinal\.venv\Lib\site-packages\django\core\handlers\exception.py", line 55, in inner
    response = get_response(request)
               ^^^^^^^^^^^^^^^^^^^^^
  File "C:\Users\ga214\Desktop\taller\proyectofinal\.venv\Lib\site-packages\django\core\handlers\base.py", line 197, in _get_response
    response = wrapped_callback(request, *callback_args, **callback_kwargs)
               ^^^^^^^^^^^^^^^^^^^^^^^^^^^^^^^^^^^^^^^^^^^^^^^^^^^^^^^^^^^^
  File "C:\Users\ga214\Desktop\taller\proyectofinal\nuevo_evento\views.py", line 75, in detalle_evento
    nota.save()
  File "C:\Users\ga214\Desktop\taller\proyectofinal\.venv\Lib\site-packages\django\db\models\base.py", line 891, in save
    self.save_base(
  File "C:\Users\ga214\Desktop\taller\proyectofinal\.venv\Lib\site-packages\django\db\models\base.py", line 997, in save_base
    updated = self._save_table(
              ^^^^^^^^^^^^^^^^^
  File "C:\Users\ga214\Desktop\taller\proyectofinal\.venv\Lib\site-packages\django\db\models\base.py", line 1160, in _save_table
    results = self._do_insert(
              ^^^^^^^^^^^^^^^^
  File "C:\Users\ga214\Desktop\taller\proyectofinal\.venv\Lib\site-packages\django\db\models\base.py", line 1201, in _do_insert
    return manager._insert(
           ^^^^^^^^^^^^^^^^
  File "C:\Users\ga214\Desktop\taller\proyectofinal\.venv\Lib\site-packages\django\db\models\manager.py", line 87, in manager_method
    return getattr(self.get_queryset(), name)(*args, **kwargs)
           ^^^^^^^^^^^^^^^^^^^^^^^^^^^^^^^^^^^^^^^^^^^^^^^^^^^
  File "C:\Users\ga214\Desktop\taller\proyectofinal\.venv\Lib\site-packages\django\db\models\query.py", line 1847, in _insert
    return query.get_compiler(using=using).execute_sql(returning_fields)
           ^^^^^^^^^^^^^^^^^^^^^^^^^^^^^^^^^^^^^^^^^^^^^^^^^^^^^^^^^^^^^
  File "C:\Users\ga214\Desktop\taller\proyectofinal\.venv\Lib\site-packages\django\db\models\sql\compiler.py", line 1836, in execute_sql
    cursor.execute(sql, params)
  File "C:\Users\ga214\Desktop\taller\proyectofinal\.venv\Lib\site-packages\django\db\backends\utils.py", line 122, in execute
    return super().execute(sql, params)
           ^^^^^^^^^^^^^^^^^^^^^^^^^^^^
  File "C:\Users\ga214\Desktop\taller\proyectofinal\.venv\Lib\site-packages\django\db\backends\utils.py", line 79, in execute
    return self._execute_with_wrappers(
           ^^^^^^^^^^^^^^^^^^^^^^^^^^^^
  File "C:\Users\ga214\Desktop\taller\proyectofinal\.venv\Lib\site-packages\django\db\backends\utils.py", line 92, in _execute_with_wrappers
    return executor(sql, params, many, context)
           ^^^^^^^^^^^^^^^^^^^^^^^^^^^^^^^^^^^^
  File "C:\Users\ga214\Desktop\taller\proyectofinal\.venv\Lib\site-packages\django\db\backends\utils.py", line 100, in _execute
    with self.db.wrap_database_errors:
         ^^^^^^^^^^^^^^^^^^^^^^^^^^^^
  File "C:\Users\ga214\Desktop\taller\proyectofinal\.venv\Lib\site-packages\django\db\utils.py", line 91, in __exit__
    raise dj_exc_value.with_traceback(traceback) from exc_value
  File "C:\Users\ga214\Desktop\taller\proyectofinal\.venv\Lib\site-packages\django\db\backends\utils.py", line 105, in _execute
    return self.cursor.execute(sql, params)
           ^^^^^^^^^^^^^^^^^^^^^^^^^^^^^^^^
  File "C:\Users\ga214\Desktop\taller\proyectofinal\.venv\Lib\site-packages\django\db\backends\sqlite3\base.py", line 354, in execute
    return super().execute(query, params)
           ^^^^^^^^^^^^^^^^^^^^^^^^^^^^^^
django.db.utils.IntegrityError: NOT NULL constraint failed: nuevo_evento_nota.usuario_id
"POST /nuevo_evento/detalle-evento/1/ HTTP/1.1" 500 151349
Internal Server Error: /nuevo_evento/detalle-evento/1/
Traceback (most recent call last):
  File "C:\Users\ga214\Desktop\taller\proyectofinal\.venv\Lib\site-packages\django\db\backends\utils.py", line 105, in _execute
    return self.cursor.execute(sql, params)
           ^^^^^^^^^^^^^^^^^^^^^^^^^^^^^^^^
  File "C:\Users\ga214\Desktop\taller\proyectofinal\.venv\Lib\site-packages\django\db\backends\sqlite3\base.py", line 354, in execute
    return super().execute(query, params)
           ^^^^^^^^^^^^^^^^^^^^^^^^^^^^^^
sqlite3.IntegrityError: NOT NULL constraint failed: nuevo_evento_nota.usuario_id

The above exception was the direct cause of the following exception:

Traceback (most recent call last):
  File "C:\Users\ga214\Desktop\taller\proyectofinal\.venv\Lib\site-packages\django\core\handlers\exception.py", line 55, in inner
    response = get_response(request)
               ^^^^^^^^^^^^^^^^^^^^^
  File "C:\Users\ga214\Desktop\taller\proyectofinal\.venv\Lib\site-packages\django\core\handlers\base.py", line 197, in _get_response
    response = wrapped_callback(request, *callback_args, **callback_kwargs)
               ^^^^^^^^^^^^^^^^^^^^^^^^^^^^^^^^^^^^^^^^^^^^^^^^^^^^^^^^^^^^
  File "C:\Users\ga214\Desktop\taller\proyectofinal\nuevo_evento\views.py", line 75, in detalle_evento
    nota.save()
  File "C:\Users\ga214\Desktop\taller\proyectofinal\.venv\Lib\site-packages\django\db\models\base.py", line 891, in save
    self.save_base(
  File "C:\Users\ga214\Desktop\taller\proyectofinal\.venv\Lib\site-packages\django\db\models\base.py", line 997, in save_base
    updated = self._save_table(
              ^^^^^^^^^^^^^^^^^
  File "C:\Users\ga214\Desktop\taller\proyectofinal\.venv\Lib\site-packages\django\db\models\base.py", line 1160, in _save_table
    results = self._do_insert(
              ^^^^^^^^^^^^^^^^
  File "C:\Users\ga214\Desktop\taller\proyectofinal\.venv\Lib\site-packages\django\db\models\base.py", line 1201, in _do_insert
    return manager._insert(
           ^^^^^^^^^^^^^^^^
  File "C:\Users\ga214\Desktop\taller\proyectofinal\.venv\Lib\site-packages\django\db\models\manager.py", line 87, in manager_method
    return getattr(self.get_queryset(), name)(*args, **kwargs)
           ^^^^^^^^^^^^^^^^^^^^^^^^^^^^^^^^^^^^^^^^^^^^^^^^^^^
  File "C:\Users\ga214\Desktop\taller\proyectofinal\.venv\Lib\site-packages\django\db\models\query.py", line 1847, in _insert
    return query.get_compiler(using=using).execute_sql(returning_fields)
           ^^^^^^^^^^^^^^^^^^^^^^^^^^^^^^^^^^^^^^^^^^^^^^^^^^^^^^^^^^^^^
  File "C:\Users\ga214\Desktop\taller\proyectofinal\.venv\Lib\site-packages\django\db\models\sql\compiler.py", line 1836, in execute_sql
    cursor.execute(sql, params)
  File "C:\Users\ga214\Desktop\taller\proyectofinal\.venv\Lib\site-packages\django\db\backends\utils.py", line 122, in execute
    return super().execute(sql, params)
           ^^^^^^^^^^^^^^^^^^^^^^^^^^^^
  File "C:\Users\ga214\Desktop\taller\proyectofinal\.venv\Lib\site-packages\django\db\backends\utils.py", line 79, in execute
    return self._execute_with_wrappers(
           ^^^^^^^^^^^^^^^^^^^^^^^^^^^^
  File "C:\Users\ga214\Desktop\taller\proyectofinal\.venv\Lib\site-packages\django\db\backends\utils.py", line 92, in _execute_with_wrappers
    return executor(sql, params, many, context)
           ^^^^^^^^^^^^^^^^^^^^^^^^^^^^^^^^^^^^
  File "C:\Users\ga214\Desktop\taller\proyectofinal\.venv\Lib\site-packages\django\db\backends\utils.py", line 100, in _execute
    with self.db.wrap_database_errors:
         ^^^^^^^^^^^^^^^^^^^^^^^^^^^^
  File "C:\Users\ga214\Desktop\taller\proyectofinal\.venv\Lib\site-packages\django\db\utils.py", line 91, in __exit__
    raise dj_exc_value.with_traceback(traceback) from exc_value
  File "C:\Users\ga214\Desktop\taller\proyectofinal\.venv\Lib\site-packages\django\db\backends\utils.py", line 105, in _execute
    return self.cursor.execute(sql, params)
           ^^^^^^^^^^^^^^^^^^^^^^^^^^^^^^^^
  File "C:\Users\ga214\Desktop\taller\proyectofinal\.venv\Lib\site-packages\django\db\backends\sqlite3\base.py", line 354, in execute
    return super().execute(query, params)
           ^^^^^^^^^^^^^^^^^^^^^^^^^^^^^^
django.db.utils.IntegrityError: NOT NULL constraint failed: nuevo_evento_nota.usuario_id
"POST /nuevo_evento/detalle-evento/1/ HTTP/1.1" 500 151349
Internal Server Error: /nuevo_evento/
Traceback (most recent call last):
  File "C:\Users\ga214\Desktop\taller\proyectofinal\.venv\Lib\site-packages\django\core\handlers\exception.py", line 55, in inner
    response = get_response(request)
               ^^^^^^^^^^^^^^^^^^^^^
  File "C:\Users\ga214\Desktop\taller\proyectofinal\.venv\Lib\site-packages\django\core\handlers\base.py", line 197, in _get_response
    response = wrapped_callback(request, *callback_args, **callback_kwargs)
               ^^^^^^^^^^^^^^^^^^^^^^^^^^^^^^^^^^^^^^^^^^^^^^^^^^^^^^^^^^^^
  File "C:\Users\ga214\Desktop\taller\proyectofinal\nuevo_evento\views.py", line 21, in nuevo_evento
    evento = form.save(commit=False)
             ^^^^^^^^^^^^^^^^^^^^^^^
  File "C:\Users\ga214\Desktop\taller\proyectofinal\nuevo_evento\forms.py", line 23, in save
    categoria, created = Categoria.objects.get_or_create(nombre=nueva_categoria)
                         ^^^^^^^^^
NameError: name 'Categoria' is not defined
"POST /nuevo_evento/ HTTP/1.1" 500 73859
